<?xml version="1.0" ?>
<!-- =================================================================================== -->
<!-- |    This document was autogenerated by xacro from robot.xacro                    | -->
<!-- |    EDITING THIS FILE BY HAND IS NOT RECOMMENDED                                 | -->
<!-- =================================================================================== -->
<robot name="lite3">
  <material name="silver">
    <color rgba="0.9137254901960784 0.9137254901960784 0.9137254901960784 1.0"/>
  </material>
  <link name="base">
    <visual>
      <origin rpy="0 0 0" xyz="0 0 0"/>
      <geometry>
        <box size="0.001 0.001 0.001"/>
      </geometry>
    </visual>
  </link>
  <joint name="floating_base" type="fixed">
    <origin rpy="0 0 0" xyz="0 0 0"/>
    <parent link="base"/>
    <child link="TORSO"/>
  </joint>
  <link name="TORSO">
    <visual>
      <geometry>
        <mesh filename="package://lite3_description/meshes/torso.obj"/>
      </geometry>
    </visual>
    <collision>
      <geometry>
        <box size="0.35 0.184 0.08"/>
      </geometry>
    </collision>
    <inertial>
      <origin xyz="0.004098 -0.000663 -0.002069"/>
      <mass value="4.130"/>
      <inertia ixx="0.016982120" ixy="2.1294E-05" ixz="6.0763E-05" iyy="0.030466501" iyz="1.7968E-05" izz="0.042609956"/>
    </inertial>
  </link>
  <joint name="imu_joint" type="fixed">
    <parent link="TORSO"/>
    <child link="imu_link"/>
    <origin rpy="0 0 0" xyz="0 0 0"/>
  </joint>
  <link name="imu_link">
    <inertial>
      <mass value="0.001"/>
      <origin rpy="0 0 0" xyz="0 0 0"/>
      <inertia ixx="0.0001" ixy="0" ixz="0" iyy="0.0001" iyz="0" izz="0.0001"/>
    </inertial>
    <visual>
      <origin rpy="0 0 0" xyz="0 0 0"/>
      <geometry>
        <box size="0.001 0.001 0.001"/>
      </geometry>
    </visual>
    <collision>
      <origin rpy="0 0 0" xyz="0 0 0"/>
      <geometry>
        <box size=".001 .001 .001"/>
      </geometry>
    </collision>
  </link>
  <joint name="FR_HipX" type="revolute">
    <origin rpy="0 0 0" xyz="0.1745 -0.062 0"/>
    <parent link="TORSO"/>
    <child link="FR_HIP"/>
    <axis xyz="-1 0 0"/>
    <dynamics damping="0.0" friction="0.1"/>
    <limit effort="24" lower="-0.42" upper="0.42" velocity="26"/>
  </joint>
  <link name="FR_HIP">
    <inertial>
      <inertia ixx="0.00014538" ixy="8.1579E-07" ixz="-1.264E-05" iyy="0.00024024" iyz="1.3443E-06" izz="0.00013038"/>
      <origin xyz="-0.0047 0.0091 -0.0018"/>
      <mass value="0.428"/>
      <inertia ixx="0.00014538" ixy="-8.1579e-07" ixz="-1.264e-05" iyy="0.00024024" iyz="-1.3443e-06" izz="0.00013038"/>
    </inertial>
    <visual>
      <geometry>
        <mesh filename="package://lite3_description/meshes/FR_hip.STL"/>
      </geometry>
      <material name="silver"/>
    </visual>
  </link>
  <joint name="FR_HipY" type="revolute">
    <origin xyz="0 -0.0955 0"/>
    <parent link="FR_HIP"/>
    <child link="FR_THIGH"/>
    <axis xyz="0 -1 0"/>
    <dynamics damping="0.0" friction="0.1"/>
    <limit effort="24" lower="-2.67" upper="0.314" velocity="26"/>
  </joint>
  <link name="FR_THIGH">
    <inertial>
      <origin rpy="0 0 0" xyz="-0.00523 0.0216 -0.0273"/>
      <mass value="0.61"/>
      <inertia ixx="0.001" ixy="2.5e-06" ixz="-0.000112" iyy="0.00116" iyz="-3.75e-07" izz="0.000268"/>
      <inertia ixx="0.001" ixy="-2.5E-06" ixz="-1.12E-04" iyy="0.00116" iyz="3.75E-07" izz="2.68E-04"/>
    </inertial>
    <visual>
      <geometry>
        <mesh filename="package://lite3_description/meshes/r_thigh.obj"/>
      </geometry>
    </visual>
    <collision>
      <origin xyz="0 0 -0.08"/>
      <geometry>
        <box size="0.02 0.02 0.16"/>
      </geometry>
    </collision>
  </link>
  <joint name="FR_Knee" type="revolute">
    <origin xyz="0 0 -0.20"/>
    <parent link="FR_THIGH"/>
    <child link="FR_SHANK"/>
    <axis xyz="0 -1 0"/>
    <dynamics damping="0.0" friction="0.1"/>
    <limit effort="36" lower="0.6" upper="2.72" velocity="17"/>
  </joint>
  <link name="FR_SHANK">
    <inertial>
      <origin xyz="0.00585 -8.732E-07 -0.12"/>
      <mass value="0.115"/>
      <inertia ixx="6.68E-04" ixy="-1.24E-08" ixz="6.91E-06" iyy="6.86E-04" iyz="5.65E-09" izz="3.155E-05"/>
    </inertial>
    <visual>
      <geometry>
        <mesh filename="package://lite3_description/meshes/shank.obj"/>
      </geometry>
    </visual>
    <collision>
      <origin xyz="0 0 -0.09"/>
      <geometry>
        <box size="0.02 0.02 0.18"/>
      </geometry>
    </collision>
  </link>
  <joint name="FR_Ankle" type="fixed">
    <origin xyz="0 0 -0.21"/>
    <parent link="FR_SHANK"/>
    <child link="FR_FOOT"/>
  </joint>
  <link name="FR_FOOT">
    <inertial>
      <mass value="0.06"/>
      <inertia ixx="4.056e-06" ixy="0.0" ixz="0.0" iyy="4.056e-06" iyz="0.0" izz="4.056e-06"/>
    </inertial>
    <collision>
      <geometry>
        <sphere radius="0.013"/>
      </geometry>
    </collision>
  </link>
  <gazebo reference="FR_HIP">
    <mu1>0.2</mu1>
    <mu2>0.2</mu2>
  </gazebo>
  <gazebo reference="FR_THIGH">
    <mu1>0.2</mu1>
    <mu2>0.2</mu2>
    <self_collide>0</self_collide>
    <kp value="1000000.0"/>
    <kd value="100.0"/>
  </gazebo>
  <gazebo reference="FR_SHANK">
    <mu1>0.6</mu1>
    <mu2>0.6</mu2>
    <self_collide>1</self_collide>
  </gazebo>
  <gazebo reference="FR_FOOT">
    <mu1>0.6</mu1>
    <mu2>0.6</mu2>
    <self_collide>1</self_collide>
    <kp value="1000000.0"/>
    <kd value="100.0"/>
  </gazebo>
  <transmission name="FR_HipX_tran">
    <type>transmission_interface/SimpleTransmission</type>
    <joint name="FR_HipX">
      <hardwareInterface>hardware_interface/EffortJointInterface</hardwareInterface>
    </joint>
    <actuator name="FR_HipX_motor">
      <mechanicalReduction>1</mechanicalReduction>
    </actuator>
  </transmission>
  <transmission name="{name}_HipY_tran">
    <type>transmission_interface/SimpleTransmission</type>
    <joint name="{name}_HipY">
      <hardwareInterface>hardware_interface/EffortJointInterface</hardwareInterface>
    </joint>
    <actuator name="{name}_HipY_motor">
      <mechanicalReduction>1</mechanicalReduction>
    </actuator>
  </transmission>
  <transmission name="{name}_Knee_tran">
    <type>transmission_interface/SimpleTransmission</type>
    <joint name="{name}_Knee">
      <hardwareInterface>hardware_interface/EffortJointInterface</hardwareInterface>
    </joint>
    <actuator name="{name}_Knee_motor">
      <mechanicalReduction>1</mechanicalReduction>
    </actuator>
  </transmission>
  <joint name="FL_HipX" type="revolute">
    <origin rpy="0 0 0" xyz="0.1745 0.062 0"/>
    <parent link="TORSO"/>
    <child link="FL_HIP"/>
    <axis xyz="-1 0 0"/>
    <dynamics damping="0.0" friction="0.1"/>
    <limit effort="24" lower="-0.42" upper="0.42" velocity="26"/>
  </joint>
  <link name="FL_HIP">
    <inertial>
      <inertia ixx="0.00014538" ixy="8.1579E-07" ixz="-1.264E-05" iyy="0.00024024" iyz="1.3443E-06" izz="0.00013038"/>
      <origin xyz="-0.0047 -0.0091 -0.0018"/>
      <mass value="0.428"/>
      <inertia ixx="0.00014538" ixy="8.1579e-07" ixz="-1.264e-05" iyy="0.00024024" iyz="1.3443e-06" izz="0.00013038"/>
    </inertial>
    <visual>
      <geometry>
        <mesh filename="package://lite3_description/meshes/FL_hip.STL"/>
      </geometry>
      <material name="silver"/>
    </visual>
  </link>
  <joint name="FL_HipY" type="revolute">
    <origin xyz="0 0.0955 0"/>
    <parent link="FL_HIP"/>
    <child link="FL_THIGH"/>
    <axis xyz="0 -1 0"/>
    <dynamics damping="0.0" friction="0.1"/>
    <limit effort="24" lower="-2.67" upper="0.314" velocity="26"/>
  </joint>
  <link name="FL_THIGH">
    <inertial>
      <origin rpy="0 0 0" xyz="-0.00523 -0.0216 -0.0273"/>
      <mass value="0.61"/>
      <inertia ixx="0.001" ixy="-2.5e-06" ixz="-0.000112" iyy="0.00116" iyz="3.75e-07" izz="0.000268"/>
      <inertia ixx="0.001" ixy="-2.5E-06" ixz="-1.12E-04" iyy="0.00116" iyz="3.75E-07" izz="2.68E-04"/>
    </inertial>
    <visual>
      <geometry>
        <mesh filename="package://lite3_description/meshes/l_thigh.obj"/>
      </geometry>
    </visual>
    <collision>
      <origin xyz="0 0 -0.08"/>
      <geometry>
        <box size="0.02 0.02 0.16"/>
      </geometry>
    </collision>
  </link>
  <joint name="FL_Knee" type="revolute">
    <origin xyz="0 0 -0.20"/>
    <parent link="FL_THIGH"/>
    <child link="FL_SHANK"/>
    <axis xyz="0 -1 0"/>
    <dynamics damping="0.0" friction="0.1"/>
    <limit effort="36" lower="0.6" upper="2.72" velocity="17"/>
  </joint>
  <link name="FL_SHANK">
    <inertial>
      <origin xyz="0.00585 -8.732E-07 -0.12"/>
      <mass value="0.115"/>
      <inertia ixx="6.68E-04" ixy="-1.24E-08" ixz="6.91E-06" iyy="6.86E-04" iyz="5.65E-09" izz="3.155E-05"/>
    </inertial>
    <visual>
      <geometry>
        <mesh filename="package://lite3_description/meshes/shank.obj"/>
      </geometry>
    </visual>
    <collision>
      <origin xyz="0 0 -0.09"/>
      <geometry>
        <box size="0.02 0.02 0.18"/>
      </geometry>
    </collision>
  </link>
  <joint name="FL_Ankle" type="fixed">
    <origin xyz="0 0 -0.21"/>
    <parent link="FL_SHANK"/>
    <child link="FL_FOOT"/>
  </joint>
  <link name="FL_FOOT">
    <inertial>
      <mass value="0.06"/>
      <inertia ixx="4.056e-06" ixy="0.0" ixz="0.0" iyy="4.056e-06" iyz="0.0" izz="4.056e-06"/>
    </inertial>
    <collision>
      <geometry>
        <sphere radius="0.013"/>
      </geometry>
    </collision>
  </link>
  <gazebo reference="FL_HIP">
    <mu1>0.2</mu1>
    <mu2>0.2</mu2>
  </gazebo>
  <gazebo reference="FL_THIGH">
    <mu1>0.2</mu1>
    <mu2>0.2</mu2>
    <self_collide>0</self_collide>
    <kp value="1000000.0"/>
    <kd value="100.0"/>
  </gazebo>
  <gazebo reference="FL_SHANK">
    <mu1>0.6</mu1>
    <mu2>0.6</mu2>
    <self_collide>1</self_collide>
  </gazebo>
  <gazebo reference="FL_FOOT">
    <mu1>0.6</mu1>
    <mu2>0.6</mu2>
    <self_collide>1</self_collide>
    <kp value="1000000.0"/>
    <kd value="100.0"/>
  </gazebo>
  <transmission name="FL_HipX_tran">
    <type>transmission_interface/SimpleTransmission</type>
    <joint name="FL_HipX">
      <hardwareInterface>hardware_interface/EffortJointInterface</hardwareInterface>
    </joint>
    <actuator name="FL_HipX_motor">
      <mechanicalReduction>1</mechanicalReduction>
    </actuator>
  </transmission>
  <transmission name="{name}_HipY_tran">
    <type>transmission_interface/SimpleTransmission</type>
    <joint name="{name}_HipY">
      <hardwareInterface>hardware_interface/EffortJointInterface</hardwareInterface>
    </joint>
    <actuator name="{name}_HipY_motor">
      <mechanicalReduction>1</mechanicalReduction>
    </actuator>
  </transmission>
  <transmission name="{name}_Knee_tran">
    <type>transmission_interface/SimpleTransmission</type>
    <joint name="{name}_Knee">
      <hardwareInterface>hardware_interface/EffortJointInterface</hardwareInterface>
    </joint>
    <actuator name="{name}_Knee_motor">
      <mechanicalReduction>1</mechanicalReduction>
    </actuator>
  </transmission>
  <joint name="HR_HipX" type="revolute">
    <origin rpy="0 0 0" xyz="-0.1745 -0.062 0"/>
    <parent link="TORSO"/>
    <child link="HR_HIP"/>
    <axis xyz="-1 0 0"/>
    <dynamics damping="0.0" friction="0.1"/>
    <limit effort="24" lower="-0.42" upper="0.42" velocity="26"/>
  </joint>
  <link name="HR_HIP">
    <inertial>
      <inertia ixx="0.00014538" ixy="8.1579E-07" ixz="-1.264E-05" iyy="0.00024024" iyz="1.3443E-06" izz="0.00013038"/>
      <origin xyz="0.0047 0.0091 -0.0018"/>
      <mass value="0.428"/>
      <inertia ixx="0.00014538" ixy="8.1579e-07" ixz="1.264e-05" iyy="0.00024024" iyz="-1.3443e-06" izz="0.00013038"/>
    </inertial>
    <visual>
      <geometry>
        <mesh filename="package://lite3_description/meshes/HR_hip.STL"/>
      </geometry>
      <material name="silver"/>
    </visual>
  </link>
  <joint name="HR_HipY" type="revolute">
    <origin xyz="0 -0.0955 0"/>
    <parent link="HR_HIP"/>
    <child link="HR_THIGH"/>
    <axis xyz="0 -1 0"/>
    <dynamics damping="0.0" friction="0.1"/>
    <limit effort="24" lower="-2.67" upper="0.314" velocity="26"/>
  </joint>
  <link name="HR_THIGH">
    <inertial>
      <origin rpy="0 0 0" xyz="-0.00523 0.0216 -0.0273"/>
      <mass value="0.61"/>
      <inertia ixx="0.001" ixy="2.5e-06" ixz="-0.000112" iyy="0.00116" iyz="-3.75e-07" izz="0.000268"/>
      <inertia ixx="0.001" ixy="-2.5E-06" ixz="-1.12E-04" iyy="0.00116" iyz="3.75E-07" izz="2.68E-04"/>
    </inertial>
    <visual>
      <geometry>
        <mesh filename="package://lite3_description/meshes/r_thigh.obj"/>
      </geometry>
    </visual>
    <collision>
      <origin xyz="0 0 -0.08"/>
      <geometry>
        <box size="0.02 0.02 0.16"/>
      </geometry>
    </collision>
  </link>
  <joint name="HR_Knee" type="revolute">
    <origin xyz="0 0 -0.20"/>
    <parent link="HR_THIGH"/>
    <child link="HR_SHANK"/>
    <axis xyz="0 -1 0"/>
    <dynamics damping="0.0" friction="0.1"/>
    <limit effort="36" lower="0.6" upper="2.72" velocity="17"/>
  </joint>
  <link name="HR_SHANK">
    <inertial>
      <origin xyz="0.00585 -8.732E-07 -0.12"/>
      <mass value="0.115"/>
      <inertia ixx="6.68E-04" ixy="-1.24E-08" ixz="6.91E-06" iyy="6.86E-04" iyz="5.65E-09" izz="3.155E-05"/>
    </inertial>
    <visual>
      <geometry>
        <mesh filename="package://lite3_description/meshes/shank.obj"/>
      </geometry>
    </visual>
    <collision>
      <origin xyz="0 0 -0.09"/>
      <geometry>
        <box size="0.02 0.02 0.18"/>
      </geometry>
    </collision>
  </link>
  <joint name="HR_Ankle" type="fixed">
    <origin xyz="0 0 -0.21"/>
    <parent link="HR_SHANK"/>
    <child link="HR_FOOT"/>
  </joint>
  <link name="HR_FOOT">
    <inertial>
      <mass value="0.06"/>
      <inertia ixx="4.056e-06" ixy="0.0" ixz="0.0" iyy="4.056e-06" iyz="0.0" izz="4.056e-06"/>
    </inertial>
    <collision>
      <geometry>
        <sphere radius="0.013"/>
      </geometry>
    </collision>
  </link>
  <gazebo reference="HR_HIP">
    <mu1>0.2</mu1>
    <mu2>0.2</mu2>
  </gazebo>
  <gazebo reference="HR_THIGH">
    <mu1>0.2</mu1>
    <mu2>0.2</mu2>
    <self_collide>0</self_collide>
    <kp value="1000000.0"/>
    <kd value="100.0"/>
  </gazebo>
  <gazebo reference="HR_SHANK">
    <mu1>0.6</mu1>
    <mu2>0.6</mu2>
    <self_collide>1</self_collide>
  </gazebo>
  <gazebo reference="HR_FOOT">
    <mu1>0.6</mu1>
    <mu2>0.6</mu2>
    <self_collide>1</self_collide>
    <kp value="1000000.0"/>
    <kd value="100.0"/>
  </gazebo>
  <transmission name="HR_HipX_tran">
    <type>transmission_interface/SimpleTransmission</type>
    <joint name="HR_HipX">
      <hardwareInterface>hardware_interface/EffortJointInterface</hardwareInterface>
    </joint>
    <actuator name="HR_HipX_motor">
      <mechanicalReduction>1</mechanicalReduction>
    </actuator>
  </transmission>
  <transmission name="{name}_HipY_tran">
    <type>transmission_interface/SimpleTransmission</type>
    <joint name="{name}_HipY">
      <hardwareInterface>hardware_interface/EffortJointInterface</hardwareInterface>
    </joint>
    <actuator name="{name}_HipY_motor">
      <mechanicalReduction>1</mechanicalReduction>
    </actuator>
  </transmission>
  <transmission name="{name}_Knee_tran">
    <type>transmission_interface/SimpleTransmission</type>
    <joint name="{name}_Knee">
      <hardwareInterface>hardware_interface/EffortJointInterface</hardwareInterface>
    </joint>
    <actuator name="{name}_Knee_motor">
      <mechanicalReduction>1</mechanicalReduction>
    </actuator>
  </transmission>
  <joint name="HL_HipX" type="revolute">
    <origin rpy="0 0 0" xyz="-0.1745 0.062 0"/>
    <parent link="TORSO"/>
    <child link="HL_HIP"/>
    <axis xyz="-1 0 0"/>
    <dynamics damping="0.0" friction="0.1"/>
    <limit effort="24" lower="-0.42" upper="0.42" velocity="26"/>
  </joint>
  <link name="HL_HIP">
    <inertial>
      <inertia ixx="0.00014538" ixy="8.1579E-07" ixz="-1.264E-05" iyy="0.00024024" iyz="1.3443E-06" izz="0.00013038"/>
      <origin xyz="0.0047 -0.0091 -0.0018"/>
      <mass value="0.428"/>
      <inertia ixx="0.00014538" ixy="-8.1579e-07" ixz="1.264e-05" iyy="0.00024024" iyz="1.3443e-06" izz="0.00013038"/>
    </inertial>
    <visual>
      <geometry>
        <mesh filename="package://lite3_description/meshes/HL_hip.STL"/>
      </geometry>
      <material name="silver"/>
    </visual>
  </link>
  <joint name="HL_HipY" type="revolute">
    <origin xyz="0 0.0955 0"/>
    <parent link="HL_HIP"/>
    <child link="HL_THIGH"/>
    <axis xyz="0 -1 0"/>
    <dynamics damping="0.0" friction="0.1"/>
    <limit effort="24" lower="-2.67" upper="0.314" velocity="26"/>
  </joint>
  <link name="HL_THIGH">
    <inertial>
      <origin rpy="0 0 0" xyz="-0.00523 -0.0216 -0.0273"/>
      <mass value="0.61"/>
      <inertia ixx="0.001" ixy="-2.5e-06" ixz="-0.000112" iyy="0.00116" iyz="3.75e-07" izz="0.000268"/>
      <inertia ixx="0.001" ixy="-2.5E-06" ixz="-1.12E-04" iyy="0.00116" iyz="3.75E-07" izz="2.68E-04"/>
    </inertial>
    <visual>
      <geometry>
        <mesh filename="package://lite3_description/meshes/l_thigh.obj"/>
      </geometry>
    </visual>
    <collision>
      <origin xyz="0 0 -0.08"/>
      <geometry>
        <box size="0.02 0.02 0.16"/>
      </geometry>
    </collision>
  </link>
  <joint name="HL_Knee" type="revolute">
    <origin xyz="0 0 -0.20"/>
    <parent link="HL_THIGH"/>
    <child link="HL_SHANK"/>
    <axis xyz="0 -1 0"/>
    <dynamics damping="0.0" friction="0.1"/>
    <limit effort="36" lower="0.6" upper="2.72" velocity="17"/>
  </joint>
  <link name="HL_SHANK">
    <inertial>
      <origin xyz="0.00585 -8.732E-07 -0.12"/>
      <mass value="0.115"/>
      <inertia ixx="6.68E-04" ixy="-1.24E-08" ixz="6.91E-06" iyy="6.86E-04" iyz="5.65E-09" izz="3.155E-05"/>
    </inertial>
    <visual>
      <geometry>
        <mesh filename="package://lite3_description/meshes/shank.obj"/>
      </geometry>
    </visual>
    <collision>
      <origin xyz="0 0 -0.09"/>
      <geometry>
        <box size="0.02 0.02 0.18"/>
      </geometry>
    </collision>
  </link>
  <joint name="HL_Ankle" type="fixed">
    <origin xyz="0 0 -0.21"/>
    <parent link="HL_SHANK"/>
    <child link="HL_FOOT"/>
  </joint>
  <link name="HL_FOOT">
    <inertial>
      <mass value="0.06"/>
      <inertia ixx="4.056e-06" ixy="0.0" ixz="0.0" iyy="4.056e-06" iyz="0.0" izz="4.056e-06"/>
    </inertial>
    <collision>
      <geometry>
        <sphere radius="0.013"/>
      </geometry>
    </collision>
  </link>
  <gazebo reference="HL_HIP">
    <mu1>0.2</mu1>
    <mu2>0.2</mu2>
  </gazebo>
  <gazebo reference="HL_THIGH">
    <mu1>0.2</mu1>
    <mu2>0.2</mu2>
    <self_collide>0</self_collide>
    <kp value="1000000.0"/>
    <kd value="100.0"/>
  </gazebo>
  <gazebo reference="HL_SHANK">
    <mu1>0.6</mu1>
    <mu2>0.6</mu2>
    <self_collide>1</self_collide>
  </gazebo>
  <gazebo reference="HL_FOOT">
    <mu1>0.6</mu1>
    <mu2>0.6</mu2>
    <self_collide>1</self_collide>
    <kp value="1000000.0"/>
    <kd value="100.0"/>
  </gazebo>
  <transmission name="HL_HipX_tran">
    <type>transmission_interface/SimpleTransmission</type>
    <joint name="HL_HipX">
      <hardwareInterface>hardware_interface/EffortJointInterface</hardwareInterface>
    </joint>
    <actuator name="HL_HipX_motor">
      <mechanicalReduction>1</mechanicalReduction>
    </actuator>
  </transmission>
  <transmission name="{name}_HipY_tran">
    <type>transmission_interface/SimpleTransmission</type>
    <joint name="{name}_HipY">
      <hardwareInterface>hardware_interface/EffortJointInterface</hardwareInterface>
    </joint>
    <actuator name="{name}_HipY_motor">
      <mechanicalReduction>1</mechanicalReduction>
    </actuator>
  </transmission>
  <transmission name="{name}_Knee_tran">
    <type>transmission_interface/SimpleTransmission</type>
    <joint name="{name}_Knee">
      <hardwareInterface>hardware_interface/EffortJointInterface</hardwareInterface>
    </joint>
    <actuator name="{name}_Knee_motor">
      <mechanicalReduction>1</mechanicalReduction>
    </actuator>
  </transmission>
</robot>
