<?xml version="1.0" encoding="utf-8"?>

<robot name="sa01">
  <link name="base">
    <inertial>
      <origin xyz="-0.030427 0.00055533 0.10697"/>
      <mass value="10.176" />
      <inertia
        ixx="0.24707543"
        ixy="0.0000714263"
        ixz="-0.017967096"
        iyy="0.21999950689"
        iyz="-0.00116322262"
        izz="0.09662582243" />
    </inertial>
    <visual>
      <geometry>
        <mesh filename="file://$(find sa01_description)/meshes/base_link.obj" />
      </geometry>
    </visual>
    <collision>
      <origin xyz="0 0 0.03"/>
      <geometry>
        <box size="0.2 0.2 0.3" />
      </geometry>
    </collision>
  </link>

  <link name="leg_l1_link">
    <inertial>
      <origin xyz="0.0003501 0.00043844 -0.0020201"/>
      <mass value="1.6592" />
      <inertia
        ixx="0.00170970094"
        ixy="0.00000339099"
        ixz="-0.00000364314"
        iyy="0.00222453198"
        iyz="-0.000018428"
        izz="0.00296249862" />
    </inertial>
    <visual>
      <geometry>
        <mesh filename="file://$(find sa01_description)/meshes/leg_link_01.obj" />
      </geometry>
    </visual>
  </link>

  <joint name="leg_l1_joint" type="revolute">
    <origin xyz="0 0.075 0"/>
    <parent link="base" />
    <child link="leg_l1_link" />
    <axis xyz="1 0 0" />
    <limit lower="-0.523" upper="0.523" effort="140" velocity="25" />
  </joint>

  <link name="leg_l2_link">
    <inertial>
      <origin xyz="0.00038352 0.0010044 -0.12214"/>
      <mass value="1.8008" />
      <inertia
        ixx="0.0028514924"
        ixy="-0.00000811841"
        ixz="0.00000081779"
        iyy="0.00367928378"
        iyz="0.00001485978"
        izz="0.00191736965" />
    </inertial>
    <visual>
      <geometry>
        <mesh filename="file://$(find sa01_description)/meshes/leg_link_02.obj" />
      </geometry>
    </visual>
  </link>

  <joint name="leg_l2_joint" type="revolute">
    <parent link="leg_l1_link" />
    <child link="leg_l2_link" />
    <axis xyz="0 0 1" />
    <limit lower="-0.3" upper="0.3" effort="140" velocity="25" />
  </joint>

  <link name="leg_l3_link">
    <inertial>
      <origin xyz="-0.0017654 0.0012877 -0.13954"/>
      <mass value="3.9299" />
      <inertia
        ixx="0.03203144433"
        ixy="0.00003937845"
        ixz="0.00141442438"
        iyy="0.03561061150"
        iyz="-0.00080953754"
        izz="0.01016719156" />
    </inertial>
    <visual>
      <geometry>
        <mesh filename="file://$(find sa01_description)/meshes/leg_link_03.obj" />
      </geometry>
    </visual>
    <collision>
      <origin xyz="0 0 -0.17"/>
      <geometry>
        <box size="0.08 0.08 0.25" />
      </geometry>
    </collision>
  </link>

  <joint name="leg_l3_joint" type="revolute">
    <origin xyz="0 0 -0.1311"/>
    <parent link="leg_l2_link" />
    <child link="leg_l3_link" />
    <axis xyz="0 1 0" />
    <limit lower="-1.204" upper="1.204" effort="140" velocity="25" />
  </joint>

  <link name="leg_l4_link">
    <inertial>
      <origin xyz="-0.00751 -0.00041 -0.16322"/>
      <mass value="2.72510" />
      <inertia
        ixx="0.03032295461"
        ixy="-0.00007371616"
        ixz="-0.00028406531"
        iyy="0.03234908064"
        iyz="0.00021740427"
        izz="0.00389340359" />
    </inertial>
    <visual>
      <geometry>
        <mesh filename="file://$(find sa01_description)/meshes/leg_link_04.obj" />
      </geometry>
    </visual>
    <collision>
      <origin xyz="0 0 -0.18"/>
      <geometry>
        <box size="0.05 0.05 0.28" />
      </geometry>
    </collision>
  </link>

  <joint name="leg_l4_joint" type="revolute">
    <origin xyz="0 5.9998E-05 -0.3"/>
    <parent link="leg_l3_link" />
    <child link="leg_l4_link" />
    <axis xyz="0 1 0" />
    <limit lower="0.0" upper="2.268" effort="140" velocity="25" />
  </joint>

  <link name="leg_l5_link">
    <inertial>
      <origin xyz="-2.5946E-10 -5E-05 -3.4499E-09"/>
      <mass value="0.16135" />
      <inertia
        ixx="3.0975E-05"
        ixy="0"
        ixz="0"
        iyy="3.1274E-05"
        iyz="0"
        izz="3.1681E-05" />
    </inertial>
    <visual>
      <geometry>
        <mesh filename="file://$(find sa01_description)/meshes/leg_link_05.obj" />
      </geometry>
    </visual>
  </link>

  <joint name="leg_l5_joint" type="revolute">
    <origin xyz="0 7.0122E-05 -0.37"/>
    <parent link="leg_l4_link" />
    <child link="leg_l5_link" />
    <axis xyz="0 1 0" />
    <limit lower="-1.0" upper="0.6" effort="24" velocity="31" />
  </joint>

  <link name="leg_l6_link">
    <inertial>
      <origin xyz="0.030366 0.0019502 -0.03549"/>
      <mass value="1.1926" />
      <inertia
        ixx="0.00105334189"
        ixy="-0.0"
        ixz="0.0"
        iyy="0.00606712875"
        iyz="0.0"
        izz="0.00646061141" />
    </inertial>
    <visual>
      <geometry>
        <mesh filename="file://$(find sa01_description)/meshes/leg_link_06.obj" />
      </geometry>
    </visual>
    <collision>
      <geometry>
        <mesh filename="file://$(find sa01_description)/meshes/leg_link_06.obj" />
      </geometry>
    </collision>
  </link>

  <joint name="leg_l6_joint" type="revolute">
    <origin xyz="0 0 0"/>
    <parent link="leg_l5_link" />
    <child link="leg_l6_link" />
    <axis xyz="1 0 0" />
    <limit lower="-0.6" upper="0.6" effort="24" velocity="31" />
  </joint>

  <link
    name="leg_r1_link">
    <inertial>
      <origin xyz="0.0003501 0.00043844 -0.0020201"/>
      <mass value="1.6592" />
      <inertia
        ixx="0.00170970094"
        ixy="0.00000339099"
        ixz="-0.00000364314"
        iyy="0.00222453198"
        iyz="-0.000018428"
        izz="0.00296249862" />
    </inertial>
    <visual>
      <geometry>
        <mesh filename="file://$(find sa01_description)/meshes/leg_link_01.obj" />
      </geometry>
    </visual>
  </link>

  <joint name="leg_r1_joint" type="revolute">
    <origin xyz="0 -0.075 0"/>
    <parent link="base" />
    <child link="leg_r1_link" />
    <axis xyz="1 0 0" />
    <limit lower="-0.523" upper="0.523" effort="140" velocity="25" />
  </joint>

  <link name="leg_r2_link">
    <inertial>
      <origin xyz="-0.00038352 -0.0010044 -0.12214"/>
      <mass value="1.8008" />
      <inertia
        ixx="0.0028514924"
        ixy="-0.00000811841"
        ixz="-0.00000081779"
        iyy="0.00367928378"
        iyz="-0.00001485978"
        izz="0.00191736965" />
    </inertial>
    <visual>
      <geometry>
        <mesh filename="file://$(find sa01_description)/meshes/leg_link_02.obj" />
      </geometry>
    </visual>
  </link>

  <joint name="leg_r2_joint" type="revolute">
    <parent link="leg_r1_link" />
    <child link="leg_r2_link" />
    <axis xyz="0 0 1" />
    <limit lower="-0.3" upper="0.3" effort="140" velocity="25" />
  </joint>

  <link name="leg_r3_link">
    <inertial>
      <origin xyz="-0.0017403 -0.0012919 -0.13954"/>
      <mass value="3.9294" />
      <inertia
        ixx="0.03202203311"
        ixy="-0.00003371707"
        ixz="0.00139789064"
        iyy="0.03559852831"
        iyz="0.00081210058"
        izz="0.01016409159" />
    </inertial>
    <visual>
      <geometry>
        <mesh filename="file://$(find sa01_description)/meshes/leg_link_03.obj" scale="1 -1 1" />
      </geometry>
    </visual>
    <collision>
      <origin xyz="0 0 -0.17"/>
      <geometry>
        <box size="0.08 0.08 0.25" />
      </geometry>
    </collision>
  </link>

  <joint name="leg_r3_joint" type="revolute">
    <origin xyz="0 0 -0.1311"/>
    <parent link="leg_r2_link" />
    <child link="leg_r3_link" />
    <axis xyz="0 1 0" />
    <limit lower="-1.204" upper="1.204" effort="140" velocity="25" />
  </joint>

  <link name="leg_r4_link">
    <inertial>
      <origin xyz="-0.00751 0.00047274 -0.16321"/>
      <mass value="2.72497" />
      <inertia
        ixx="0.03032110864"
        ixy="0.00007373941"
        ixz="-0.00028430637"
        iyy="0.03234733040"
        iyz="-0.00021746443"
        izz="0.00389339565" />
    </inertial>
    <visual>
      <geometry>
        <mesh filename="file://$(find sa01_description)/meshes/leg_link_04.obj" scale="1 -1 1" />
      </geometry>
    </visual>
    <collision>
      <origin xyz="0 0 -0.18"/>
      <geometry>
        <box size="0.05 0.05 0.28" />
      </geometry>
    </collision>
  </link>

  <joint name="leg_r4_joint" type="revolute">
    <origin xyz="0 -5.9998E-05 -0.3"/>
    <parent link="leg_r3_link" />
    <child link="leg_r4_link" />
    <axis xyz="0 1 0" />
    <limit lower="0.0" upper="2.268" effort="140" velocity="25" />
  </joint>

  <link name="leg_r5_link">
    <inertial>
      <origin xyz="2.5946E-10 5E-05 -3.4499E-09"/>
      <mass value="0.16135" />
      <inertia
        ixx="3.0975E-05"
        ixy="0"
        ixz="0"
        iyy="3.1274E-05"
        iyz="0"
        izz="3.1274E-05" />
    </inertial>
    <visual>
      <geometry>
        <mesh filename="file://$(find sa01_description)/meshes/leg_link_05.obj" />
      </geometry>
    </visual>
  </link>

  <joint name="leg_r5_joint" type="revolute">
    <origin xyz="0 -7.0122E-05 -0.37"/>
    <parent link="leg_r4_link" />
    <child link="leg_r5_link" />
    <axis xyz="0 1 0" />
    <limit lower="-1.0" upper="0.6" effort="24" velocity="31" />
  </joint>

  <link name="leg_r6_link">
    <inertial>
      <origin xyz="0.030366 -0.0019504 -0.03549"/>
      <mass value="1.1926" />
      <inertia
        ixx="0.00105336111"
        ixy="0.0"
        ixz="0.0"
        iyy="0.00606728572"
        iyz="-0.0"
        izz="0.00646075577" />
    </inertial>
    <visual>
      <geometry>
        <mesh filename="file://$(find sa01_description)/meshes/leg_link_06.obj" scale="1 -1 1"/>
      </geometry>
    </visual>
    <collision>
      <geometry>
        <mesh filename="file://$(find sa01_description)/meshes/leg_link_06.obj" scale="1 -1 1"/>
      </geometry>
    </collision>
  </link>

  <joint name="leg_r6_joint" type="revolute">
    <parent link="leg_r5_link" />
    <child link="leg_r6_link" />
    <axis xyz="1 0 0" />
    <limit lower="-0.6" upper="0.6" effort="24" velocity="31" />
  </joint>

</robot>